[2025-10-28T02:29:32.412+0000] {local_task_job_runner.py:120} INFO - ::group::Pre task execution logs
[2025-10-28T02:29:32.422+0000] {taskinstance.py:2076} INFO - Dependencies all met for dep_context=non-requeueable deps ti=<TaskInstance: ecommerce_pipeline.extract_raw manual__2025-10-27T21:30:00+00:00 [queued]>
[2025-10-28T02:29:32.425+0000] {taskinstance.py:2076} INFO - Dependencies all met for dep_context=requeueable deps ti=<TaskInstance: ecommerce_pipeline.extract_raw manual__2025-10-27T21:30:00+00:00 [queued]>
[2025-10-28T02:29:32.425+0000] {taskinstance.py:2306} INFO - Starting attempt 1 of 1
[2025-10-28T02:29:32.431+0000] {taskinstance.py:2330} INFO - Executing <Task(KubernetesPodOperator): extract_raw> on 2025-10-27 21:30:00+00:00
[2025-10-28T02:29:32.436+0000] {standard_task_runner.py:90} INFO - Running: ['***', 'tasks', 'run', 'ecommerce_pipeline', 'extract_raw', 'manual__2025-10-27T21:30:00+00:00', '--job-id', '5', '--raw', '--subdir', 'DAGS_FOLDER/ecommerce_pipeline_dag.py', '--cfg-path', '/tmp/tmp10ubh6uh']
[2025-10-28T02:29:32.438+0000] {standard_task_runner.py:91} INFO - Job 5: Subtask extract_raw
[2025-10-28T02:29:32.437+0000] {logging_mixin.py:188} WARNING - /home/***/.local/lib/python3.12/site-packages/***/task/task_runner/standard_task_runner.py:62 DeprecationWarning: This process (pid=3365) is multi-threaded, use of fork() may lead to deadlocks in the child.
[2025-10-28T02:29:32.439+0000] {standard_task_runner.py:64} INFO - Started process 3366 to run task
[2025-10-28T02:29:32.466+0000] {task_command.py:426} INFO - Running <TaskInstance: ecommerce_pipeline.extract_raw manual__2025-10-27T21:30:00+00:00 [running]> on host 1fa078f1d346
[2025-10-28T02:29:32.509+0000] {taskinstance.py:2648} INFO - Exporting env vars: AIRFLOW_CTX_DAG_OWNER='***' AIRFLOW_CTX_DAG_ID='ecommerce_pipeline' AIRFLOW_CTX_TASK_ID='extract_raw' AIRFLOW_CTX_EXECUTION_DATE='2025-10-27T21:30:00+00:00' AIRFLOW_CTX_TRY_NUMBER='1' AIRFLOW_CTX_DAG_RUN_ID='manual__2025-10-27T21:30:00+00:00'
[2025-10-28T02:29:32.509+0000] {taskinstance.py:430} INFO - ::endgroup::
[2025-10-28T02:29:32.525+0000] {pod.py:1121} INFO - Building pod extractor-nbe2c2yu with labels: {'dag_id': 'ecommerce_pipeline', 'task_id': 'extract_raw', 'run_id': 'manual__2025-10-27T2130000000-825b7e876', 'kubernetes_pod_operator': 'True', 'try_number': '1'}
[2025-10-28T02:29:32.541+0000] {connectionpool.py:872} WARNING - Retrying (Retry(total=2, connect=None, read=None, redirect=None, status=None)) after connection broken by 'NewConnectionError('<urllib3.connection.HTTPSConnection object at 0xffff8b8c3d10>: Failed to establish a new connection: [Errno 111] Connection refused')': /api/v1/namespaces/ecommerce/pods?labelSelector=dag_id%3Decommerce_pipeline%2Ckubernetes_pod_operator%3DTrue%2Crun_id%3Dmanual__2025-10-27T2130000000-825b7e876%2Ctask_id%3Dextract_raw%2Calready_checked%21%3DTrue%2C%21***-worker
[2025-10-28T02:29:32.541+0000] {connectionpool.py:872} WARNING - Retrying (Retry(total=1, connect=None, read=None, redirect=None, status=None)) after connection broken by 'NewConnectionError('<urllib3.connection.HTTPSConnection object at 0xffff8b7520f0>: Failed to establish a new connection: [Errno 111] Connection refused')': /api/v1/namespaces/ecommerce/pods?labelSelector=dag_id%3Decommerce_pipeline%2Ckubernetes_pod_operator%3DTrue%2Crun_id%3Dmanual__2025-10-27T2130000000-825b7e876%2Ctask_id%3Dextract_raw%2Calready_checked%21%3DTrue%2C%21***-worker
[2025-10-28T02:29:32.543+0000] {connectionpool.py:872} WARNING - Retrying (Retry(total=0, connect=None, read=None, redirect=None, status=None)) after connection broken by 'NewConnectionError('<urllib3.connection.HTTPSConnection object at 0xffff8b751fa0>: Failed to establish a new connection: [Errno 111] Connection refused')': /api/v1/namespaces/ecommerce/pods?labelSelector=dag_id%3Decommerce_pipeline%2Ckubernetes_pod_operator%3DTrue%2Crun_id%3Dmanual__2025-10-27T2130000000-825b7e876%2Ctask_id%3Dextract_raw%2Calready_checked%21%3DTrue%2C%21***-worker
[2025-10-28T02:29:32.543+0000] {taskinstance.py:441} INFO - ::group::Post task execution logs
[2025-10-28T02:29:32.543+0000] {taskinstance.py:2905} ERROR - Task failed with exception
Traceback (most recent call last):
  File "/home/airflow/.local/lib/python3.12/site-packages/urllib3/connection.py", line 203, in _new_conn
    sock = connection.create_connection(
           ^^^^^^^^^^^^^^^^^^^^^^^^^^^^^
  File "/home/airflow/.local/lib/python3.12/site-packages/urllib3/util/connection.py", line 85, in create_connection
    raise err
  File "/home/airflow/.local/lib/python3.12/site-packages/urllib3/util/connection.py", line 73, in create_connection
    sock.connect(sa)
ConnectionRefusedError: [Errno 111] Connection refused

The above exception was the direct cause of the following exception:

Traceback (most recent call last):
  File "/home/airflow/.local/lib/python3.12/site-packages/urllib3/connectionpool.py", line 791, in urlopen
    response = self._make_request(
               ^^^^^^^^^^^^^^^^^^^
  File "/home/airflow/.local/lib/python3.12/site-packages/urllib3/connectionpool.py", line 492, in _make_request
    raise new_e
  File "/home/airflow/.local/lib/python3.12/site-packages/urllib3/connectionpool.py", line 468, in _make_request
    self._validate_conn(conn)
  File "/home/airflow/.local/lib/python3.12/site-packages/urllib3/connectionpool.py", line 1097, in _validate_conn
    conn.connect()
  File "/home/airflow/.local/lib/python3.12/site-packages/urllib3/connection.py", line 611, in connect
    self.sock = sock = self._new_conn()
                       ^^^^^^^^^^^^^^^^
  File "/home/airflow/.local/lib/python3.12/site-packages/urllib3/connection.py", line 218, in _new_conn
    raise NewConnectionError(
urllib3.exceptions.NewConnectionError: <urllib3.connection.HTTPSConnection object at 0xffff8b7521b0>: Failed to establish a new connection: [Errno 111] Connection refused

The above exception was the direct cause of the following exception:

Traceback (most recent call last):
  File "/home/airflow/.local/lib/python3.12/site-packages/airflow/models/taskinstance.py", line 465, in _execute_task
    result = _execute_callable(context=context, **execute_callable_kwargs)
             ^^^^^^^^^^^^^^^^^^^^^^^^^^^^^^^^^^^^^^^^^^^^^^^^^^^^^^^^^^^^^
  File "/home/airflow/.local/lib/python3.12/site-packages/airflow/models/taskinstance.py", line 432, in _execute_callable
    return execute_callable(context=context, **execute_callable_kwargs)
           ^^^^^^^^^^^^^^^^^^^^^^^^^^^^^^^^^^^^^^^^^^^^^^^^^^^^^^^^^^^^
  File "/home/airflow/.local/lib/python3.12/site-packages/airflow/models/baseoperator.py", line 401, in wrapper
    return func(self, *args, **kwargs)
           ^^^^^^^^^^^^^^^^^^^^^^^^^^^
  File "/home/airflow/.local/lib/python3.12/site-packages/airflow/providers/cncf/kubernetes/operators/pod.py", line 591, in execute
    return self.execute_sync(context)
           ^^^^^^^^^^^^^^^^^^^^^^^^^^
  File "/home/airflow/.local/lib/python3.12/site-packages/airflow/providers/cncf/kubernetes/operators/pod.py", line 601, in execute_sync
    self.pod = self.get_or_create_pod(  # must set `self.pod` for `on_kill`
               ^^^^^^^^^^^^^^^^^^^^^^^^^^^^^^^^^^^^^^^^^^^^^^^^^^^^^^^^^^^^
  File "/home/airflow/.local/lib/python3.12/site-packages/airflow/providers/cncf/kubernetes/operators/pod.py", line 559, in get_or_create_pod
    pod = self.find_pod(self.namespace or pod_request_obj.metadata.namespace, context=context)
          ^^^^^^^^^^^^^^^^^^^^^^^^^^^^^^^^^^^^^^^^^^^^^^^^^^^^^^^^^^^^^^^^^^^^^^^^^^^^^^^^^^^^
  File "/home/airflow/.local/lib/python3.12/site-packages/airflow/providers/cncf/kubernetes/operators/pod.py", line 532, in find_pod
    pod_list = self.client.list_namespaced_pod(
               ^^^^^^^^^^^^^^^^^^^^^^^^^^^^^^^^
  File "/home/airflow/.local/lib/python3.12/site-packages/kubernetes/client/api/core_v1_api.py", line 15823, in list_namespaced_pod
    return self.list_namespaced_pod_with_http_info(namespace, **kwargs)  # noqa: E501
           ^^^^^^^^^^^^^^^^^^^^^^^^^^^^^^^^^^^^^^^^^^^^^^^^^^^^^^^^^^^^
  File "/home/airflow/.local/lib/python3.12/site-packages/kubernetes/client/api/core_v1_api.py", line 15942, in list_namespaced_pod_with_http_info
    return self.api_client.call_api(
           ^^^^^^^^^^^^^^^^^^^^^^^^^
  File "/home/airflow/.local/lib/python3.12/site-packages/kubernetes/client/api_client.py", line 348, in call_api
    return self.__call_api(resource_path, method,
           ^^^^^^^^^^^^^^^^^^^^^^^^^^^^^^^^^^^^^^
  File "/home/airflow/.local/lib/python3.12/site-packages/kubernetes/client/api_client.py", line 180, in __call_api
    response_data = self.request(
                    ^^^^^^^^^^^^^
  File "/home/airflow/.local/lib/python3.12/site-packages/kubernetes/client/api_client.py", line 373, in request
    return self.rest_client.GET(url,
           ^^^^^^^^^^^^^^^^^^^^^^^^^
  File "/home/airflow/.local/lib/python3.12/site-packages/kubernetes/client/rest.py", line 244, in GET
    return self.request("GET", url,
           ^^^^^^^^^^^^^^^^^^^^^^^^
  File "/home/airflow/.local/lib/python3.12/site-packages/kubernetes/client/rest.py", line 217, in request
    r = self.pool_manager.request(method, url,
        ^^^^^^^^^^^^^^^^^^^^^^^^^^^^^^^^^^^^^^
  File "/home/airflow/.local/lib/python3.12/site-packages/urllib3/_request_methods.py", line 110, in request
    return self.request_encode_url(
           ^^^^^^^^^^^^^^^^^^^^^^^^
  File "/home/airflow/.local/lib/python3.12/site-packages/urllib3/_request_methods.py", line 143, in request_encode_url
    return self.urlopen(method, url, **extra_kw)
           ^^^^^^^^^^^^^^^^^^^^^^^^^^^^^^^^^^^^^
  File "/home/airflow/.local/lib/python3.12/site-packages/urllib3/poolmanager.py", line 443, in urlopen
    response = conn.urlopen(method, u.request_uri, **kw)
               ^^^^^^^^^^^^^^^^^^^^^^^^^^^^^^^^^^^^^^^^^
  File "/home/airflow/.local/lib/python3.12/site-packages/urllib3/connectionpool.py", line 875, in urlopen
    return self.urlopen(
           ^^^^^^^^^^^^^
  File "/home/airflow/.local/lib/python3.12/site-packages/urllib3/connectionpool.py", line 875, in urlopen
    return self.urlopen(
           ^^^^^^^^^^^^^
  File "/home/airflow/.local/lib/python3.12/site-packages/urllib3/connectionpool.py", line 875, in urlopen
    return self.urlopen(
           ^^^^^^^^^^^^^
  File "/home/airflow/.local/lib/python3.12/site-packages/urllib3/connectionpool.py", line 845, in urlopen
    retries = retries.increment(
              ^^^^^^^^^^^^^^^^^^
  File "/home/airflow/.local/lib/python3.12/site-packages/urllib3/util/retry.py", line 515, in increment
    raise MaxRetryError(_pool, url, reason) from reason  # type: ignore[arg-type]
    ^^^^^^^^^^^^^^^^^^^^^^^^^^^^^^^^^^^^^^^^^^^^^^^^^^^
urllib3.exceptions.MaxRetryError: HTTPSConnectionPool(host='127.0.0.1', port=64816): Max retries exceeded with url: /api/v1/namespaces/ecommerce/pods?labelSelector=dag_id%3Decommerce_pipeline%2Ckubernetes_pod_operator%3DTrue%2Crun_id%3Dmanual__2025-10-27T2130000000-825b7e876%2Ctask_id%3Dextract_raw%2Calready_checked%21%3DTrue%2C%21***-worker (Caused by NewConnectionError('<urllib3.connection.HTTPSConnection object at 0xffff8b7521b0>: Failed to establish a new connection: [Errno 111] Connection refused'))
[2025-10-28T02:29:32.557+0000] {taskinstance.py:1206} INFO - Marking task as FAILED. dag_id=ecommerce_pipeline, task_id=extract_raw, run_id=manual__2025-10-27T21:30:00+00:00, execution_date=20251027T213000, start_date=20251028T022932, end_date=20251028T022932
[2025-10-28T02:29:32.737+0000] {standard_task_runner.py:110} ERROR - Failed to execute job 5 for task extract_raw (HTTPSConnectionPool(host='127.0.0.1', port=64816): Max retries exceeded with url: /api/v1/namespaces/ecommerce/pods?labelSelector=dag_id%3Decommerce_pipeline%2Ckubernetes_pod_operator%3DTrue%2Crun_id%3Dmanual__2025-10-27T2130000000-825b7e876%2Ctask_id%3Dextract_raw%2Calready_checked%21%3DTrue%2C%21***-worker (Caused by NewConnectionError('<urllib3.connection.HTTPSConnection object at 0xffff8b7521b0>: Failed to establish a new connection: [Errno 111] Connection refused')); 3366)
[2025-10-28T02:29:32.746+0000] {local_task_job_runner.py:243} INFO - Task exited with return code 1
[2025-10-28T02:29:32.762+0000] {taskinstance.py:3503} INFO - 0 downstream tasks scheduled from follow-on schedule check
[2025-10-28T02:29:32.764+0000] {local_task_job_runner.py:222} INFO - ::endgroup::
